Workbook

Sheet Exercício - Matriz de avaliação
B1: Projeto Incursões de Campo Plano Brasil Nordeste de Transformação Ecológica (PTE-NE) Matriz de Avaliação de Iniciativas
A2: ID | B2: Iniciativas | C2: Objetivo | D2: Temática principal | E2: Organização Vinculante | F2: CNPJ | G2: Data de fundação | H2: CNAE principal | I2: Endereço | J2: Latitude | K2: Longitude | L2: Avaliador(a) | M2: Critérios de Estratificação | U2: Critérios de Avaliação | AE2: Análise e evidências
M3: Município | N3: Estado | O3: Biomas | P3: Eixos | Q3: Eixo Secundário | R3: Setor | S3: Natureza Jurídica | T3: Salvaguardas socioambientais mínimas | U3: Relevância territorial | V3: Adaptação e/ou mitigação climática | W3: Fortalecimento das cadeias produtivas sustentáveis do Nordeste | X3: Viabilidade operacional | Y3: Potencial de replicabilidade/escala | Z3: Inovação tecnológica e social | AA3: Potencial de atração de investimentos verdes/alinhamento a fontes de financiamento climático | AB3: Inclusão produtiva (trabalho digno) | AC3: Equidade de gênero, raça e etnia (povos e comunidades tradiocionais) | AD3: Governança multinível | AE3: Pontuação
A4: =IF($B4="","",COUNTA($B$4:$B4)) -> 1 | B4: Acreditar Microcrédito | C4: Oferecer microcrédito produtivo orientado e educação financeira para grupo de mulheres e jovens, com foco em pequenos empreendimentos e agricultura familiar. O projeto tem apoio da Aliança Empreendedora. | D4: Microcrédito; Finanças solidárias | E4: Acreditar Sociedade de Crédito ao Microempreendedor (com apoio da Aliança Empreendedora) | F4: 08.834.501/0001-85 | G4: 27/04/2007 | H4: 6499-9/05 – Concessão de crédito pelas OSCIP | I4: Rua José de Albuquerque, 27, Apto 101, Centro, CEP 55620-000, Glória do Goitá – PE – Brasil | J4: -8.0017 | K4: -35.2928 | L4: =IF($P4="","",IF(OR(LEFT($P4,2)="1.",LEFT($P4,2)="4."),"Lucas",IF(OR(LEFT($P4,2)="2.",LEFT($P4,2)="3."),"Caio","Leide"))) -> Lucas | M4: Glória do Goitá | N4: PE | O4: Mata Atlântica | P4: 1. Finanças Sustentáveis e Inclusivas | R4: Terciário | S4: Associação Privada | AE4: =SUM(R4:AD4) -> 0
A5: =IF($B5="","",COUNTA($B$4:$B5)) -> 2 | B5: Banco Palmas | C5: Democratizar o acesso a serviços financeiros e bancários para a população de baixa renda do Conjunto Palmeiras, impulsionando o desenvolvimento socioeconômico local por meio de banco comunitário, microcrédito, moeda social e apoio a empreendedores do bairro | D5: Banco comunitário; moeda social | E5: Instituto Palmas de Desenvolvimento e Socioeconomia Solidária | F5: 05.705.438/0001-99 | G5: 17/06/2003 | H5: 9430-8/00 - Atividades de associações de defesa de direitos sociais | I5: Av. Valparaíso, 620–698, Conjunto Palmeiras, CEP 60870-440, Fortaleza – CE – Brasil | J5: -3.7319 | K5: -38.5267 | L5: =IF($P5="","",IF(OR(LEFT($P5,2)="1.",LEFT($P5,2)="4."),"Lucas",IF(OR(LEFT($P5,2)="2.",LEFT($P5,2)="3."),"Caio","Leide"))) -> Lucas | M5: Fortaleza | N5: CE | O5: Mata Atlântica | P5: 1. Finanças Sustentáveis e Inclusivas | R5: Terciário | S5: Associação Privada | AE5: =SUM(R5:AD5) -> 0
A6: =IF($B6="","",COUNTA($B$4:$B6)) -> 3 | B6: COGEFUR – Conselho Gestor do Fundo Rotativo | C6: Articular e gerir fundos rotativos solidários em rede, fortalecendo cooperativas de crédito, associações comunitárias e iniciativas de agricultura familiar por meio de linhas de capital de giro e instrumentos de finanças solidárias. | D6: Economia solidária; microcrédito | E6: Conselho Gestor do Fundo Rotativo (COGEFUR) | F6: 04.578.438/0001-02 | G6: 04/07/2001 | H6: 9430-8/00 - Atividades de associações de defesa de direitos sociais | I6: BR-116, km 566, Sítio Alagoinhas, Armazém da Agricultura Familiar, CEP 48.700-000, Serrinha – BA – Brasil | J6: -11.6644 | K6: -39.0078 | L6: =IF($P6="","",IF(OR(LEFT($P6,2)="1.",LEFT($P6,2)="4."),"Lucas",IF(OR(LEFT($P6,2)="2.",LEFT($P6,2)="3."),"Caio","Leide"))) -> Lucas | M6: Serrinha | N6: BA | O6: Caatinga | P6: 1. Finanças Sustentáveis e Inclusivas | R6: Terciário | S6: Associação Privada | AE6: =SUM(R6:AD6) -> 0
A7: =IF($B7="","",COUNTA($B$4:$B7)) -> 4 | B7: Banco Comunitário de Araçoiaba | C7: Promover inclusão financeira na RM de Recife por meio da moeda social Caiana, estimulando consumo em comércios locais e acesso a crédito popular. | D7: Economia solidária; microcrédito | E7: Associação Banco da Cidade (em parceria com a Realiz) | F7: Não localizado | G7: Não Localizado | H7: Não Localizado | I7: Av. João Pessoa a Guerra, nº 5 – Centro | J7: -7.7869 | K7: -35.0922 | L7: =IF($P7="","",IF(OR(LEFT($P7,2)="1.",LEFT($P7,2)="4."),"Lucas",IF(OR(LEFT($P7,2)="2.",LEFT($P7,2)="3."),"Caio","Leide"))) -> Lucas | M7: Araçoiaba | N7: PE | O7: Mata Atlântica | P7: 1. Finanças Sustentáveis e Inclusivas | R7: Terciário | S7: Não Localizado | AE7: =SUM(R7:AD7) -> 0
A8: =IF($B8="","",COUNTA($B$4:$B8)) -> 5 | B8: Rede de Ativadores de Crédito Socioambiental (Conexsus) | C8: Implantar uma rede de ativadores e ativadoras de crédito socioambiental, formada por técnicos/as locais vinculados a negócios comunitários, para destravar o acesso ao crédito rural (especialmente Pronaf) por agricultores familiares, povos e comunidades tradicionais e organizações da sociobiodiversidade, combinando assistência técnica, educação financeira e financiamento crescente para aumento de renda e qualificação produtiva. | D8: Microcrédito; Finanças solidárias | E8: Instituto Conexões Sustentáveis (Conexsus) | F8: 10.980.503/0001-24 | G8: 27/05/2009 | H8: 9430-8/00 - Atividades de associações de defesa de direitos sociais | I8: Avenida Rio Branco, 131, sala 203 – Centro, CEP 20040-006, Rio de Janeiro – RJ | J8: -22.9068 | K8: -43.1729 | L8: =IF($P8="","",IF(OR(LEFT($P8,2)="1.",LEFT($P8,2)="4."),"Lucas",IF(OR(LEFT($P8,2)="2.",LEFT($P8,2)="3."),"Caio","Leide"))) -> Lucas | N8: BA | O8: Mata Atlântica, Caatinga, Cerrado | P8: 1. Finanças Sustentáveis e Inclusivas | R8: Terciário | S8: Associação Privada | AE8: =SUM(R8:AD8) -> 0
A9: =IF($B9="","",COUNTA($B$4:$B9)) -> 6 | B9: Rede Xique Xique de Comercialização Solidária | C9: Organizar grupos de agricultores/as familiares e empreendimentos de economia solidária para produzir, comercializar e certificar alimentos agroecológicos com base em certificação orgânica participativa, articulando agroecologia, feminismo e juventude. | D9: Certificação; Serviços ecossistêmicos | E9: Associação de Comercialização Solidária Xique-Xique | F9: 07.194.162/0001-57 | G9: 31/01/2005 | H9: 9430-8/00 - Atividades de associações de defesa de direitos sociais | I9: Rua Luiz Rola, 113, Costa e Silva, Mossoró. | J9: -5.1875 | K9: -37.3441 | L9: =IF($P9="","",IF(OR(LEFT($P9,2)="1.",LEFT($P9,2)="4."),"Lucas",IF(OR(LEFT($P9,2)="2.",LEFT($P9,2)="3."),"Caio","Leide"))) -> Lucas | M9: Mossoró | N9: RN | O9: Caatinga | P9: 1. Finanças Sustentáveis e Inclusivas | R9: Terciário | S9: Associação Privada | AE9: =SUM(R9:AD9) -> 0
A10: =IF($B10="","",COUNTA($B$4:$B10)) -> 7 | B10: ID Hub Brazil (ID Incubator) | C10: Iniciativa entre o governo brasileiro e o governo britânico para formação de um Centro de Descarbonização da Indústria do Brasil, é uma experiência piloto com abrangência nacional e com foco na NIB. Funciona como um escritório de apoio e suporte aos projetos industriais que buscam se adaptar ao processo de transformação ecológica da economia brasileira | D10: Facillity; Hub | E10: MDIC – Ministério do Desenvolvimento, Indústria, Comércio e Serviços (parceria UNIDO/DESNZ-Reino Unido) | F10: 00.394.478/0001-43 | G10: 29/11/1974 | H10: 8411-6/00 - Administração pública em geral | I10: Esplanada dos Ministérios, Bloco J, sala 400, CEP 70053-900, Brasília – DF (sede do MDIC, coordenador da iniciativa) | J10: -15.7942 | K10: -47.8822 | L10: =IF($P10="","",IF(OR(LEFT($P10,2)="1.",LEFT($P10,2)="4."),"Lucas",IF(OR(LEFT($P10,2)="2.",LEFT($P10,2)="3."),"Caio","Leide"))) -> Lucas | M10: Brasília | N10: BA, PE, CE, RN, AL, PI, PB, SE, MA | O10: Cerrado, Caatinga, Mata Atlântica, Amazônia | P10: 1. Finanças Sustentáveis e Inclusivas | R10: Terciário | S10: Órgão Público do Poder Executivo Federal | AE10: =SUM(R10:AD10) -> 0
A11: =IF($B11="","",COUNTA($B$4:$B11)) -> 8 | B11: Projeto Pacto Global de Jovens pelo Clima - ONU | C11: Preparar jovens estudantes, por meio da educação ambiental ativa e participativa, para ocupar os espaços de poder ativamente na luta por justiça socioambiental no contexto das crises climáticas para que se tornem " sentinelas" em defesa do desenvolvimento sustentável local. | D11: Educação ambiental, soluções inovadoras de impacto social. | E11: Organização das Nações Unidas (ONU) – Pacto Global | F11: 37.321.091/0001-77 | G11: 11/05/2020 | H11: 9430-8/00 - Atividades de associações de defesa de direitos sociais | I11: Centro de Estudos Avançados, Campus Recife da UFPE, Biblioteca Central -segundo andar, Avenida Reitor Joaquim Amazonas s/n; CEP 50740-570. | J11: -8.0476 | K11: -34.877 | L11: =IF($P11="","",IF(OR(LEFT($P11,2)="1.",LEFT($P11,2)="4."),"Lucas",IF(OR(LEFT($P11,2)="2.",LEFT($P11,2)="3."),"Caio","Leide"))) -> Caio | M11: Recife | N11: PE | O11: Mata Atlântica | P11: 2. Adensamento Tecnológico | R11: Terciário | S11: Associação Privada | AE11: =SUM(R11:AD11) -> 0
A12: =IF($B12="","",COUNTA($B$4:$B12)) -> 9 | B12: OXETECH | C12: Promover capacitação técnica e profissiional de qualidade na área de tecnologia e fomentar o empreendedorismo local e a atração de investimentos. | D12: Capacitação técnica e profissional em tecnologia, empreendedorismo | E12: Governo do Estado de Alagoas – Secretaria de Estado da Ciência, Tecnologia e Inovação (Secti/AL) | F12: 04.007.216/0001-30 | G12: 04/08/2000 | H12: 8411-6/00 - Administração pública em geral | I12: Sevretaria de Estado, da Ciência, da Tecnologia e da Inovação - Rua Barão de Jaraguá 580, Maceió, AL, 57022-140 | J12: -9.6498 | K12: -35.7089 | L12: =IF($P12="","",IF(OR(LEFT($P12,2)="1.",LEFT($P12,2)="4."),"Lucas",IF(OR(LEFT($P12,2)="2.",LEFT($P12,2)="3."),"Caio","Leide"))) -> Caio | M12: Maceió | N12: AL | O12: Caatinga | P12: 2. Adensamento Tecnológico | R12: Terciário | S12: Órgão Público do Poder Executivo Estadual | AE12: =SUM(R12:AD12) -> 0
A13: =IF($B13="","",COUNTA($B$4:$B13)) -> 10 | B13: Rede MCTI/EMBRAPII de Inovação em Inteligência Artificial | C13: Fomentar a capacidade produtiva e a competitividade das empresas brasileiras por meio do uso de tecnologias de fronteiras no processo produtivo da indústria nacional | D13: Investimento em PD&I, aumento capacidade produtiva e competitividade de empresas brasileiras | E13: MCTI – Ministério da Ciência, Tecnologia e Inovação / EMBRAPII | F13: 03.132.745/0001-00 | G13: 30/04/1999 | H13: 8411-6/00 - Administração pública em geral | I13: Rua Nogueira Acioli, 621 - Aldeota. Cep: 60110-140, CE. | J13: -3.7319 | K13: -38.5267 | L13: =IF($P13="","",IF(OR(LEFT($P13,2)="1.",LEFT($P13,2)="4."),"Lucas",IF(OR(LEFT($P13,2)="2.",LEFT($P13,2)="3."),"Caio","Leide"))) -> Caio | M13: Fortaleza | N13: BA, PE, CE, RN, AL, PI, PB, SE, MA | O13: Mata Atlântica, Cerrado, Amazônia, Caatinga | P13: 2. Adensamento Tecnológico | R13: Terciário | S13: Órgão Público do Poder Executivo Federal | AE13: =SUM(R13:AD13) -> 0
A14: =IF($B14="","",COUNTA($B$4:$B14)) -> 11 | B14: Programa Jovem Empreendedor Primeiros Passos JEPP - SEBRAE | C14: Estimular a criatividade e o pensamento crítico, fomentando a “mentalidade empreendedora" de alunos do ensino fundamental de forma lúdica com histórias com temáticas diversas, dente elas a sustentabilidade. | D14: Educação empreendedora no ensino básico | E14: SEBRAE – Serviço Brasileiro de Apoio às Micro e Pequenas Empresas | F14: 00.330.845/0001-45 | G14: 24/08/1972 | H14: 7020-4/00 - Atividades de consultoria em gestão empresarial | I14: Endereço: Av. Manoel Lourenço Cavalcante - Nova Corrente, Corrente - PI, CEP - 64980-000 | J14: -10.4434 | K14: -45.1619 | L14: =IF($P14="","",IF(OR(LEFT($P14,2)="1.",LEFT($P14,2)="4."),"Lucas",IF(OR(LEFT($P14,2)="2.",LEFT($P14,2)="3."),"Caio","Leide"))) -> Caio | M14: Corrente | N14: PI, CE, MA | O14: Cerrado, Caatinga, Mata Atlântica, Amazônia | P14: 2. Adensamento Tecnológico | R14: Terciário | S14: Serviço Social Autônomo | AE14: =SUM(R14:AD14) -> 0
A15: =IF($B15="","",COUNTA($B$4:$B15)) -> 12 | B15: Projeto Etnocaatinga | C15: Atuar na conservação e recuperação da Caatinga em territórios tradicionais, utilizando tecnologias sociais e promovendo a inclusão produtiva das comunidades locais. | D15: Recaatingamento, tecnologias sociais e inclusão produtiva de comunidades tradicionais e povos originários | E15: Projeto Etnocaatinga (organização executora a confirmar) | F15: 00.348.003/0001-10 | G15: 02/05/1973 | H15: 7210-0/00 - Pesquisa e desenvolvimento experimental em ciências físicas e naturais | I15: Projeto atua em 13 territórios tradicionais nos estados da Bahia, Pernambuco e Piauí. Endereço da Embrapa Semiárido: Rodovia BR-428, Km 152, Zona Rural. Petrolina-PE | CEP: 56.334-899 | J15: -9.3891 | K15: -40.5028 | L15: =IF($P15="","",IF(OR(LEFT($P15,2)="1.",LEFT($P15,2)="4."),"Lucas",IF(OR(LEFT($P15,2)="2.",LEFT($P15,2)="3."),"Caio","Leide"))) -> Caio | M15: Petrolina | N15: BA, PE, PI | O15: Caatinga | P15: 2. Adensamento Tecnológico | R15: Terciário | S15: Empresa Pública | AE15: =SUM(R15:AD15) -> 0
A16: =IF($B16="","",COUNTA($B$4:$B16)) -> 13 | B16: Parque Tecnológico Porto Digital - PE | C16: Atuar como um robusto ecossistema de inovação que integra empresas, governos, universidades, organizações diversas na área de Tecnologia dinamizando a região e alavancando projetos em TI e Economia criativa | D16: Ecossistema de inovação, PD&I, Inovação, Negócios, Empreendedorismo Inovador, Economia criativa | E16: Núcleo de Gestão do Porto Digital (NGPD) | F16: 04.203.075/0001-20 | G16: 19/12/2000 | H16: 9430-8/00 - Atividades de associações de defesa de direitos sociais | I16: Cais do Apolo, 222 - Bairro do Recife CEP: 50030-230 Recife - Pernambuco - Brasil | J16: -8.0476 | K16: -34.877 | L16: =IF($P16="","",IF(OR(LEFT($P16,2)="1.",LEFT($P16,2)="4."),"Lucas",IF(OR(LEFT($P16,2)="2.",LEFT($P16,2)="3."),"Caio","Leide"))) -> Caio | M16: Recife | N16: PE | O16: Mata Atlântica | P16: 2. Adensamento Tecnológico | R16: Terciário | S16: Associação Privada | AE16: =SUM(R16:AD16) -> 0
A17: =IF($B17="","",COUNTA($B$4:$B17)) -> 14 | B17: Vale do Dendê | C17: Fomentar ecossistemas de inovação e criatividade com foco em diversidade atuando em 4 frentes: aceleração de negócios, promoções de eventos, Hubs de apoio para empreendedores e inovação | D17: Ecossistema de inovação, empreendedorismo inovador da perifeira. | E17: Vale do Dendê (holding social) | F17: 31.186.223/0001-19 | G17: 31/07/2018 | H17: 8599-6/04 - Treinamento em desenvolvimento profissional e gerencial | I17: Vale do Dendê - Av. Vale do Tororó, Estação da Lapa, s/n - Loja 44 e Vale do Dendê - Pelourinho, R. das Laranjeiras, 2 | J17: -12.9777 | K17: -38.5016 | L17: =IF($P17="","",IF(OR(LEFT($P17,2)="1.",LEFT($P17,2)="4."),"Lucas",IF(OR(LEFT($P17,2)="2.",LEFT($P17,2)="3."),"Caio","Leide"))) -> Caio | M17: Salvador | N17: BA | O17: Mata Atlântica | P17: 2. Adensamento Tecnológico | R17: Terciário | S17: Associação Privada | AE17: =SUM(R17:AD17) -> 0
A18: =IF($B18="","",COUNTA($B$4:$B18)) -> 15 | B18: Programa Sertão Vivo | C18: Fortalecer a agricultura familiar no Semiárido, ampliando a resiliência climática, a segurança hídrica e a inclusão produtiva por meio de práticas agroecológicas e investimentos em infraestrutura rural. | D18: Agroecologia, convivência com o Semiárido | E18: Governo Federal – Ministério do Desenvolvimento Agrário e Agricultura Familiar (MDA), com apoio do FIDA | F18: 01.612.452/0001-97 | G18: 08/01/1997 | H18: 8411-6/00 - Administração pública em geral | I18: Av. República do Chile, 100 – 17º andar, Rio de Janeiro – RJ, CEP 20031-917. | J18: -22.9068 | K18: -43.1729 | L18: =IF($P18="","",IF(OR(LEFT($P18,2)="1.",LEFT($P18,2)="4."),"Lucas",IF(OR(LEFT($P18,2)="2.",LEFT($P18,2)="3."),"Caio","Leide"))) -> Caio | N18: SE, AL, PE | O18: Caatinga | P18: 3. Bioeconomia e Sistemas Agroalimentares Adaptados | R18: Terciário | S18: Órgão Público do Poder Executivo Federal | AE18: =SUM(R18:AD18) -> 0
A19: =IF($B19="","",COUNTA($B$4:$B19)) -> 16 | B19: Rota de Saberes e Sabores do Semiárido | C19: Valorizar saberes tradicionais, produtos da sociobiodiversidade e gastronomia regional, criando rotas de turismo de base comunitária que geram renda e fortalecem identidades locais. | D19: Turismo comunitário sustentável, cadeias agroalimentares regionais e valorização cultural. | E19: Embrapa Alimentos e Territórios | F19: 00.348.003/0025-98 | G19: 02/10/2018 | H19: 7210-0/00 - Pesquisa e desenvolvimento experimental em ciências físicas e naturais | I19: R. Cincinato Pinto, 348 - Térreo - Centro, Maceió - AL, 57020-050 | J19: -9.6619375 | K19: -35.740684 | L19: =IF($P19="","",IF(OR(LEFT($P19,2)="1.",LEFT($P19,2)="4."),"Lucas",IF(OR(LEFT($P19,2)="2.",LEFT($P19,2)="3."),"Caio","Leide"))) -> Caio | N19: AL | O19: Caatinga | P19: 3. Bioeconomia e Sistemas Agroalimentares Adaptados | R19: Terciário | S19: Empresa Pública | AE19: =SUM(R19:AD19) -> 0
A20: =IF($B20="","",COUNTA($B$4:$B20)) -> 17 | B20: Rede BATUC - Turismo Comunitário da Bahia | C20: Promover o turismo comunitário em comunidades tradicionais da Bahia, fortalecendo economias locais, autonomia social, práticas culturais e conservação ambiental. | D20: Turismo comunitário, economia solidária e valorização da sociobiodiversidade. | E20: Rede BATUC – Turismo Comunitário da Bahia | F20: 08.579.242/0001-93 | G20: 01/01/2007 | H20: 8411-6/00 - Administração pública em geral | I20: Av. Tancredo Neves, 776 – Caminho das Árvores, Salvador/BA – CEP 41.820-904 | J20: -12.9777 | K20: -38.5016 | L20: =IF($P20="","",IF(OR(LEFT($P20,2)="1.",LEFT($P20,2)="4."),"Lucas",IF(OR(LEFT($P20,2)="2.",LEFT($P20,2)="3."),"Caio","Leide"))) -> Caio | M20: Salvador | N20: BA | O20: Mata Atlântica, Caatinga, Cerrado | P20: 3. Bioeconomia e Sistemas Agroalimentares Adaptados | R20: Terciário | S20: Órgão Público do Poder Executivo Estadual | AE20: =SUM(R20:AD20) -> 0
A21: =IF($B21="","",COUNTA($B$4:$B21)) -> 18 | B21: Associação das Comunidades Negras Rurais Quilombolas do Maranhão (ACONERUQ) | C21: Fortalecer a autonomia produtiva e territorial de mulheres quilombolas no Nordeste, promovendo práticas agroecológicas, uso sustentável da sociobiodiversidade e integração a cadeias solidárias e comunitárias da bioeconomia. | D21: Bioeconomia comunitária, Gênero e justiça socioambiental. Patrimônio Genético, Repartição de Benefícios e Legislação | E21: Associação das Comunidades Negras Rurais Quilombolas do Maranhão (ACONERUQ) | F21: 02.786.414/0001-13 | G21: 14/10/1998 | H21: 9430-8/00 - Atividades de associações de defesa de direitos sociais | I21: Rua do Sol, 363, Altos, Centro, CEP 65020-590, São Luís – MA (sede da ACONERUQ) | J21: -2.5391 | K21: -44.2829 | L21: =IF($P21="","",IF(OR(LEFT($P21,2)="1.",LEFT($P21,2)="4."),"Lucas",IF(OR(LEFT($P21,2)="2.",LEFT($P21,2)="3."),"Caio","Leide"))) -> Caio | M21: São Luís | N21: MA | O21: Amazônia, Cerrado | P21: 3. Bioeconomia e Sistemas Agroalimentares Adaptados | R21: Terciário | S21: Associação Privada | AE21: =SUM(R21:AD21) -> 0
A22: =IF($B22="","",COUNTA($B$4:$B22)) -> 19 | B22: Territórios da Cidadania – Plataforma Territorial de Inclusão Produtiva e Bioeconomia Comunitária | C22: Promover o desenvolvimento territorial sustentável no Nordeste, fortalecendo a inclusão produtiva, a participação social e a articulação entre políticas públicas para reduzir desigualdades socioeconômicas, estimular atividades produtivas sustentáveis e ampliar o acesso a direitos em territórios rurais, tradicionais e vulnerabilizados. | D22: Desenvolvimento territorial sustentável e inclusão produtiva, com foco em organização social, governança territorial e ampliação do acesso a políticas públicas. | E22: Governo Federal – Programa Territórios da Cidadania (articulação interministerial) | F22: 01.612.452/0001-97 | G22: 08/01/1997 | H22: 8411-6/00 - Administração pública em geral | L22: =IF($P22="","",IF(OR(LEFT($P22,2)="1.",LEFT($P22,2)="4."),"Lucas",IF(OR(LEFT($P22,2)="2.",LEFT($P22,2)="3."),"Caio","Leide"))) -> Caio | N22: BA, PE, CE, RN, AL, PI, PB, SE, MA | O22: Mata Atlântica | P22: 3. Bioeconomia e Sistemas Agroalimentares Adaptados | R22: Terciário | S22: Órgão Público do Poder Executivo Federal | AE22: =SUM(R22:AD22) -> 0
A23: =IF($B23="","",COUNTA($B$4:$B23)) -> 20 | B23: Rede Nordeste de Sociobiodiversidade da Caatinga (Redeser–Terra Plantar) - Consolidação de uma economia de baixo carbono baseada na biodiversidade da Caatinga | C23: Promover uma economia regional de baixo carbono no Semiárido nordestino, por meio do uso sustentável da biodiversidade da Caatinga, da inovação produtiva, da restauração ecológica e da organização socioprodutiva de comunidades rurais, fortalecendo cadeias da sociobiodiversidade, ampliando a agregação de valor e garantindo a implementação efetiva da meta de desmatamento zero. | D23: Rastreabilidade e Mercados Sustentáveis, Bioeconomia de baixo carbono e sistemas produtivos sustentáveis baseados na biodiversidade da Caatinga. | E23: Fundação Araripe | F23: Não localizado | G23: Não localizado | H23: Não localizado | I23: Projeto de abrangência regional (Caatinga/NE); ações de referência no Centro Xingó de Convivência com o Semiárido, Piranhas – AL | J23: -9.6242 | K23: -37.7569 | L23: =IF($P23="","",IF(OR(LEFT($P23,2)="1.",LEFT($P23,2)="4."),"Lucas",IF(OR(LEFT($P23,2)="2.",LEFT($P23,2)="3."),"Caio","Leide"))) -> Caio | M23: Piranhas | N23: AL | O23: Caatinga | P23: 3. Bioeconomia e Sistemas Agroalimentares Adaptados | R23: Terciário | S23: Não localizado | AE23: =SUM(R23:AD23) -> 0
A24: =IF($B24="","",COUNTA($B$4:$B24)) -> 21 | B24: Green Energy Park (Piauí) | C24: Estabelecer um polo de produção e exportação de Hidrogênio H2V e seus derivados (principalmente Amônia Verde, NH3V) no litoral do Piauí. A iniciativa visa aproveitar o abundante potencial eólico e solar da região para gerar energia limpa em grande escala, descarbonizar o transporte marítimo e a indústria global, e impulsionar a industrialização verde do estado. | D24: Transição Energética e a Industrialização Verde; produção de Hidrogênio Verde H2V e Amônia Verde NH3V | E24: Green Energy Park Piaui LTDA (GEP-PI) | F24: 54.443.328/0001-01 | G24: 22/03/2024 | H24: 2014-2/00 - Fabricação de gases industriais | I24: Investe Piauí: Av. João XXIII, 6611 – 1º andar, Bairro São Cristovão, Teresina (PI). | J24: -5.0892 | K24: -42.8019 | L24: =IF($P24="","",IF(OR(LEFT($P24,2)="1.",LEFT($P24,2)="4."),"Lucas",IF(OR(LEFT($P24,2)="2.",LEFT($P24,2)="3."),"Caio","Leide"))) -> Lucas | M24: Teresina | N24: PI | O24: Cerrado, Caatinga | P24: 4. Transição Energética | R24: Secundário | S24: Sociedade Empresária Limitada | AE24: =SUM(R24:AD24) -> 0
A25: =IF($B25="","",COUNTA($B$4:$B25)) -> 22 | B25: Logística verde e transição para operações sustentáveis no Porto de Suape (PE) | C25: Transformar o complexo industrial portuário em um polo de energia verde e um corredor logístico descarbonizado. Isso será atingido por meio da atração de projetos de Hidrogênio Verde H2V e seus derivados (como amônia aerde e e-metanol) para descarbonizar as operações portuárias, o transporte marítimo e a indústria local, garantindo eficiência e sustentabilidade ambiental na gestão de resíduos e infraestrutura. | D25: Descarbonização da cadeia logística; industrialização verde. | E25: Complexo Industrial Portuário de Suape – Governo do Estado de Pernambuco | F25: 11.448.933/0001-62 | G25: 10/04/1979 | H25: 5231-1/02 - Atividades do operador portuário | I25: Complexo de Suape (Administração): Rodovia PE-60, Km 10 – Engenho Massangana, Ipojuca/PE, CEP 55592-900 SEDEPE (coordenação política/transição verde): Rua Imperial, 1600 – Bloco A, Bairro São José, Recife/PE, CEP 50090-000 | J25: -8.3993 | K25: -35.0639 | L25: =IF($P25="","",IF(OR(LEFT($P25,2)="1.",LEFT($P25,2)="4."),"Lucas",IF(OR(LEFT($P25,2)="2.",LEFT($P25,2)="3."),"Caio","Leide"))) -> Lucas | M25: Ipojuca | N25: PE | O25: Mata Atlântica | P25: 4. Transição Energética | R25: Terciário | S25: Empresa Pública | AE25: =SUM(R25:AD25) -> 0
A26: =IF($B26="","",COUNTA($B$4:$B26)) -> 23 | B26: SENAI CIMATEC – Formação, inovação tecnológica e transição energética (BA) | C26: Ser um complexo de educação profissional, pesquisa aplicada e inovação tecnológica, voltado à capacitação de mão de obra especializada e ao desenvolvimento de tecnologias limpas em áreas como hidrogênio verde, bioenergia, armazenamento e smart grids, promovendo a industrialização e a transição energética do Nordeste. | D26: Inovação tecnológica e a formação profissional qualificada com foco em H2V, bioenergia e sistemas inteligentes. | E26: SENAI – Departamento Regional da Bahia (mantenedora do CIMATEC) | F26: 03.795.071/0001-16 | G26: 03/05/2000 | H26: 8599-6/99 - Outras atividades de ensino não especificadas anteriormente | I26: Endereço: Avenida Orlando Gomes, 1845 – Piatã, Salvador – BA, CEP 41650-010. | J26: -12.9777 | K26: -38.5016 | L26: =IF($P26="","",IF(OR(LEFT($P26,2)="1.",LEFT($P26,2)="4."),"Lucas",IF(OR(LEFT($P26,2)="2.",LEFT($P26,2)="3."),"Caio","Leide"))) -> Lucas | M26: Salvador | N26: BA | O26: Mata Atlântica | P26: 4. Transição Energética | R26: Terciário | S26: Serviço Social Autônomo | AE26: =SUM(R26:AD26) -> 0
A27: =IF($B27="","",COUNTA($B$4:$B27)) -> 24 | B27: LabSolar+ – Pesquisa, inovação e capacitação em energia solar (RN) | C27: Atuar como um polo de pesquisa aplicada, inovação tecnológica e capacitação profissional em energia solar fotovoltaica, com foco na expansão da geração distribuída, eficiência energética, desenvolvimento de sistemas híbridos solar/eólico e armazenamento de energia (BESS) no Nordeste. | D27: Pesquisa Aplicada e Capacitação Profissional focada na expansão da energia solar fotovoltaica e Geração Distribuída | E27: LabSolar+ – instituição de pesquisa (RN) (organização executora a confirmar) | F27: 10.877.412/0001-68 | G27: 29/12/2008 | H27: 8541-4/00 - Educação profissional de nível técnico | I27: IFRN – Instituto Federal do Rio Grande do Norte, Campus Natal - Zona Norte. Rua Brusque, 37, Potengi, Natal – RN. CEP: 59129-600 | J27: -5.7945 | K27: -35.211 | L27: =IF($P27="","",IF(OR(LEFT($P27,2)="1.",LEFT($P27,2)="4."),"Lucas",IF(OR(LEFT($P27,2)="2.",LEFT($P27,2)="3."),"Caio","Leide"))) -> Lucas | M27: Natal | N27: RN | O27: Mata Atlântica, Caatinga | P27: 4. Transição Energética | R27: Terciário | S27: Órgão Público do Poder Executivo Federal | AE27: =SUM(R27:AD27) -> 0
A28: =IF($B28="","",COUNTA($B$4:$B28)) -> 25 | B28: Programa 1 Milhão de Tetos Solares (P1MTS) – Nordeste | C28: Promover a produção descentralizada de energia fotovoltaica em residências e unidades comunitárias do Semiárido, fortalecendo a autonomia energética, a inclusão social e a justiça climática para famílias de baixa renda e em situação de vulnerabilidade. | D28: Justiça climática e inclusão social; produção fotovoltaica comunitária; redução da vulnerabilidade de famílias rurais do Semiárido. | E28: Governo Federal / estaduais – Programa 1 Milhão de Tetos Solares (articulação ASA/sociedade civil) | F28: 05.080.329/0001-23 | G28: 2002 | H28: 9430-8/00 - Atividades de associações de defesa de direitos sociais | I28: Rua Monte Alverne, 287, Bairro do Hipódromo, Recife - PE CEP: 52041-610. | J28: -8.0476 | K28: -34.877 | L28: =IF($P28="","",IF(OR(LEFT($P28,2)="1.",LEFT($P28,2)="4."),"Lucas",IF(OR(LEFT($P28,2)="2.",LEFT($P28,2)="3."),"Caio","Leide"))) -> Lucas | M28: Recife | N28: BA, PE, CE, RN, AL, PI, PB, SE, MA | O28: Mata Atlântica, Caatinga, Cerrado, Amazônia | P28: 4. Transição Energética | R28: Terciário | S28: Associação Privada | AE28: =SUM(R28:AD28) -> 0
A29: =IF($B29="","",COUNTA($B$4:$B29)) -> 26 | B29: Programa Água Doce – Segurança hídrica e integração energética no Semiárido | C29: Promover a dessalinização de águas salobras e salinas, garantindo o abastecimento seguro de água para consumo humano e atividades produtivas em comunidades rurais do Semiárido brasileiro, integrando essa solução com a geração de energia renovável descentralizada. | D29: Segurança hídrica e a resiliência climática; inovação tecnológica da dessalinização; Geração Distribuída (GD). | E29: Governo Federal – Ministério da Integração e do Desenvolvimento Regional (Programa Água Doce/MMA) | F29: 03.353.358/0001-96 | G29: 24/08/1999 | H29: 8411-6/00 - Administração pública em geral | I29: Esplanada dos Ministérios, Bloco E, 3º Andar, Sala 355, Zona Cívico-Administrativa, Brasília/DF. | J29: -15.7942 | K29: -47.8822 | L29: =IF($P29="","",IF(OR(LEFT($P29,2)="1.",LEFT($P29,2)="4."),"Lucas",IF(OR(LEFT($P29,2)="2.",LEFT($P29,2)="3."),"Caio","Leide"))) -> Lucas | M29: Brasília | N29: BA, PE, CE, RN, AL, PI, PB, SE, MA | O29: Mata Atlântica, Caatinga, Cerrado, Amazônia | P29: 4. Transição Energética | R29: Terciário | S29: Órgão Público do Poder Executivo Federal | AE29: =SUM(R29:AD29) -> 0
A30: =IF($B30="","",COUNTA($B$4:$B30)) -> 27 | B30: Programa Nacional de Biodigestores e Biogás – Inclusão energética e fortalecimento produtivo no meio rural | C30: Promover a implantação descentralizada de biodigestores em propriedades rurais, assentamentos e comunidades tradicionais, com foco na produção de biogás, biometano e biofertilizantes, visando a mitigação de emissões, a inclusão energética e o fortalecimento produtivo da agricultura familiar. | D30: Bioenergia; inclusão energética no meio rural; produção descentralizada de biogás/biometano e biofertilizantes. | E30: Governo Federal – programa nacional de biodigestores e biogás (órgão gestor a confirmar) | F30: Não localizado | G30: 04/06/2002 | H30: Não Localizado | I30: Esplanada dos Ministérios, Bloco A CEP: 70054-900 | J30: -15.7942 | K30: -47.8822 | L30: =IF($P30="","",IF(OR(LEFT($P30,2)="1.",LEFT($P30,2)="4."),"Lucas",IF(OR(LEFT($P30,2)="2.",LEFT($P30,2)="3."),"Caio","Leide"))) -> Lucas | M30: Brasília | N30: BA, PE, CE, RN, AL, PI, PB, SE, MA | O30: Mata Atlântica, Caatinga, Cerrado, Amazônia | P30: 4. Transição Energética | R30: Terciário | AE30: =SUM(R30:AD30) -> 0
A31: =IF($B31="","",COUNTA($B$4:$B31)) -> 28 | B31: Programa Mais Luz para a Amazônia e o Semiárido – Expansão da Energia Renovável para Comunidades Isoladas | C31: Garantir o acesso universal à energia elétrica por meio da instalação de sistemas renováveis descentralizados (principalmente solar fotovoltaico off-grid), com foco em regiões isoladas, comunidades rurais difusas, assentamentos, territórios quilombolas e indígenas no Semiárido e na Amazônia, onde a extensão da rede convencional é inviável técnica ou economicamente. | D31: Universalização do acesso à energia elétrica; inclusão energética. | E31: Governo Federal – Ministério de Minas e Energia (Programa Mais Luz para a Amazônia) | F31: 37.115.383/0001-53 | G31: 12/05/1992 | H31: 8411-6/00 - Administração pública em geral | I31: Edifício sede do Ministério de Minas e Energia, Esplanada dos Ministérios, Bloco "U", Térreo Sala 30, CEP 70.065-900, Brasília, Distrito Federal. | J31: -15.7942 | K31: -47.8822 | L31: =IF($P31="","",IF(OR(LEFT($P31,2)="1.",LEFT($P31,2)="4."),"Lucas",IF(OR(LEFT($P31,2)="2.",LEFT($P31,2)="3."),"Caio","Leide"))) -> Lucas | M31: Brasília | N31: BA, PE, CE, RN, AL, PI, PB, SE, MA | O31: Caatinga, Amazônia | P31: 4. Transição Energética | R31: Terciário | S31: Órgão Público do Poder Executivo Federal | AE31: =SUM(R31:AD31) -> 0
A32: =IF($B32="","",COUNTA($B$4:$B32)) -> 29 | B32: APROBAMBU (MA) | C32: Promover uma cadeia de valor sustentável de bioeconomia e bioenergia, utilizando o bambu para a produção de etanol de segunda geração (2G), biomassa energética e bioprodutos de alto valor, fortalecendo a inovação tecnológica e o desenvolvimento rural. | D32: Bioeconomia e bioenergia de segunda geração | E32: APROBAMBU – Associação dos Produtores de Bambu (MA) | F32: 36.690.138/0001-07 | G32: 31/08/2018 | H32: 7210-0/00 - Pesquisa e desenvolvimento experimental em ciências físicas e naturais | I32: Embrapa Meio-Norte (Centro de Pesquisa de São Luís/MA) Praça da República, 140 – Centro. CEP: 65020-200 Cidade/Estado: São Luís, Maranhão (MA) Embrapa Agroenergia (Centro Nacional de Pesquisa em Agroenergia) Parque Estação Biológica (PqEB), s/n, Asa Norte CEP:70770-901 Cidade/Estado: Brasília, Distrito Federal (DF) | J32: -2.5391 | K32: -44.2829 | L32: =IF($P32="","",IF(OR(LEFT($P32,2)="1.",LEFT($P32,2)="4."),"Lucas",IF(OR(LEFT($P32,2)="2.",LEFT($P32,2)="3."),"Caio","Leide"))) -> Lucas | M32: São Luís | N32: MA | O32: Amazônia | P32: 4. Transição Energética | R32: Terciário | S32: Associação Privada | AE32: =SUM(R32:AD32) -> 0
A33: =IF($B33="","",COUNTA($B$4:$B33)) -> 30 | B33: Raízes Solares (MA) – Programa comunitário de inclusão energética e geração fotovoltaica | C33: Implantar um modelo inovador de transição energética justa em comunidades tradicionais (quilombolas), instalando uma usina solar fotovoltaica comunitária para reduzir a pobreza energética, fortalecer a autonomia econômica e produtiva (agroecologia) e criar um Fundo Econômico Comunitário autossustentável para reinvestimento. | D33: Transição energética justa; autonomia comunitária; geração fotovoltaica comunitária; fortalecimento econômico em territórios quilombolas e tradicionais. | E33: Raízes Solares – programa comunitário (organização executora a confirmar) | F33: 07.060.718/0001-12 | G33: 28/08/2004 | H33: 8550-3/02 - Atividades de apoio à educação, exceto caixas escolares | I33: SEDEPE - Governo do Maranhão Avenida Dom Pedro II, Edifício Nagib Haick, 1º Andar, Centro, São Luís/MA Fundação Sousândrade de Apoio ao Desenvolvimento da UFMA (FSADU) Rua Urano, 45, Jardim Renascença, São Luís/MA | J33: -2.5391 | K33: -44.2829 | L33: =IF($P33="","",IF(OR(LEFT($P33,2)="1.",LEFT($P33,2)="4."),"Lucas",IF(OR(LEFT($P33,2)="2.",LEFT($P33,2)="3."),"Caio","Leide"))) -> Lucas | M33: São Luís | N33: MA | O33: Amazônia | P33: 4. Transição Energética | R33: Terciário | S33: Fundação Privada | AE33: =SUM(R33:AD33) -> 0
A34: =IF($B34="","",COUNTA($B$4:$B34)) -> 31 | B34: SEDEPE – Articulação de Políticas Estaduais de Transição Verde (PE) | C34: Coordenar e integrar as políticas públicas do Governo de Pernambuco para a transição energética e sustentável, atraindo investimentos verdes (como o H2V) e promovendo a descarbonização da economia, articulando essas ações com a sociedade civil organizada, ONGs e movimentos sociais para garantir a justiça socioambiental e a inclusão produtiva no estado. | D34: Transição Energética justa e sustentável | E34: Governo do Estado de Pernambuco – Secretaria de Desenvolvimento Econômico (SEDEPE) | F34: 10.571.982/0001-25 | G34: 14/02/1975 | H34: 8411-6/00 - Administração pública em geral | I34: Av. Conselheiro Rosa e Silva, 781, Aflitos. CEP: 52020-220 | J34: -8.0476 | K34: -34.877 | L34: =IF($P34="","",IF(OR(LEFT($P34,2)="1.",LEFT($P34,2)="4."),"Lucas",IF(OR(LEFT($P34,2)="2.",LEFT($P34,2)="3."),"Caio","Leide"))) -> Lucas | M34: Recife | N34: PE | O34: Mata Atlântica, Caatinga | P34: 4. Transição Energética | R34: Terciário | S34: Órgão Público do Poder Executivo Estadual | AE34: =SUM(R34:AD34) -> 0
A35: =IF($B35="","",COUNTA($B$4:$B35)) -> 32 | B35: Programa Sertão Vivo (NE) – Resiliência climática, produção rural sustentável e uso produtivo da energia em territórios semiáridos | C35: Garantir a resiliência climática e autonomia produtiva no Semiárido, integrando o uso produtivo da energia solar fotovoltaica (principalmente em sistemas de bombeamento) à infraestrutura hídrica e à agroecologia. A iniciativa visa substituir motores a diesel para reduzir custos e mitigar GEE, garantindo o suprimento seguro de água e energia para a produção familiar (irrigação, resfriamento), o que fortalece a segurança alimentar e a justiça socioambiental. | D35: Resiliência climática; sustentabilidade produtiva no Semiárido; integração de tecnologias sociais; infraestrutura hídrica; uso produtivo da energia solar. | E35: Governo Federal – Ministério do Desenvolvimento Agrário e Agricultura Familiar (MDA), com apoio do FIDA | F35: 01.612.452/0001-97 | G35: 08/01/1997 | H35: 8411-6/00 - Administração pública em geral | I35: Brasília: SAUS, Quadra 1, Lotes 3A e 5, Bloco I - Sobreloja - Sala 201 - Brasília/DF - CEP: 70070-010 Salvador: 3ª Avenida, nº 310 - Centro Administrativo da Bahia. CEP 41.745-005 - Salvador/BA | J35: -15.7942 | K35: -47.8822 | L35: =IF($P35="","",IF(OR(LEFT($P35,2)="1.",LEFT($P35,2)="4."),"Lucas",IF(OR(LEFT($P35,2)="2.",LEFT($P35,2)="3."),"Caio","Leide"))) -> Lucas | M35: Brasília | N35: BA, PE, CE, RN, AL, PI, PB, SE | O35: Cerrado, Caatinga | P35: 4. Transição Energética | R35: Terciário | S35: Órgão Público do Poder Executivo Federal | AE35: =SUM(R35:AD35) -> 0
A36: =IF($B36="","",COUNTA($B$4:$B36)) -> 33 | B36: Crédito de Carbono Integral (CCI-BSHE): Metodologia Brasileira para Certificação em Caatinga | C36: Desenvolver e validar uma metodologia brasileira para certificar a absorção de carbono em vegetação nativa da Caatinga, criando um Mercado de Crédito de Carbono Social que remunera a conservação do bioma e promove a justiça socioambiental para pequenos produtores rurais. | D36: Mercado de carbono social; conservação da Caatinga | E36: Associação dos Produtores de Crédito de Carbono Social do Bioma Caatinga | F36: 48.123.437/0001-49 | G36: 11/08/2022 | H36: 9430-8/00 - Atividades de associações de defesa de direitos sociais | I36: Fazenda Olho D'Aguinha S/N, Delmiro Gouveia - AL Zona Rural CEP: 57480-000 | J36: -9.3856 | K36: -37.9966 | L36: =IF($P36="","",IF(OR(LEFT($P36,2)="1.",LEFT($P36,2)="4."),"Lucas",IF(OR(LEFT($P36,2)="2.",LEFT($P36,2)="3."),"Caio","Leide"))) -> Lucas | M36: Delmiro Gouveia | N36: AL | O36: Caatinga | P36: 4. Transição Energética | R36: Terciário | S36: Associação Privada | AE36: =SUM(R36:AD36) -> 0
A37: =IF($B37="","",COUNTA($B$4:$B37)) -> 34 | B37: Programa Município Selo Verde (CE) | C37: Certificação ambiental pública que reconhece e valoriza os municípios que adotam políticas e práticas efetivas de conservação ambiental e uso sustentável dos recursos naturais, promovendo a melhoria contínua da gestão ambiental local. | D37: Governança Ambiental; Indicadores de Sustentabilidade Ambiental | E37: Governo do Estado do Ceará – Secretaria do Meio Ambiente (Programa Município Selo Verde) | F37: 22.156.351/0001-29 | H37: 8411-6/00 - Administração pública em geral | I37: Av. Pontes Vieira, 2666 - Dionísio Torres, Fortaleza - CE | J37: -3.7319 | K37: -38.5267 | L37: =IF($P37="","",IF(OR(LEFT($P37,2)="1.",LEFT($P37,2)="4."),"Lucas",IF(OR(LEFT($P37,2)="2.",LEFT($P37,2)="3."),"Caio","Leide"))) -> Leide | M37: Fortaleza | N37: CE | O37: Mata Atlântica, Caatinga, Cerrado | P37: 5. Economia Circular e Solidária | R37: Terciário | S37: Órgão Público do Poder Executivo Estadual | AE37: =SUM(R37:AD37) -> 0
A38: =IF($B38="","",COUNTA($B$4:$B38)) -> 35 | B38: Projeto Bahia Solidária | C38: O programa busca articular políticas públicas de inclusão produtiva, inovação social e valorização de empreendimentos econômicos solidários (EES), especialmente de base comunitária e cooperativa de territórios de identidade da Bahia. | D38: Economia Solidária; Microcrédito, Assistência técnica,Compras Públicas Sustentáveis | E38: Governo do Estado da Bahia – Secretaria de Justiça, Direitos Humanos e Desenvolvimento Social (Bahia Solidária) | F38: 21.730.529/0001-30 | G38: 01/01/2015 | H38: 8411-6/00 - Administração pública em geral | I38: Av. Luís Viana Filho, 2ª Avenida, Plataforma III, nº 200, CAB, Salvador, BA | J38: -12.9777 | K38: -38.5016 | L38: =IF($P38="","",IF(OR(LEFT($P38,2)="1.",LEFT($P38,2)="4."),"Lucas",IF(OR(LEFT($P38,2)="2.",LEFT($P38,2)="3."),"Caio","Leide"))) -> Leide | M38: Salvador | N38: BA | O38: Mata Atlântica, Caatinga, Cerrado | P38: 5. Economia Circular e Solidária | R38: Terciário | S38: Órgão Público do Poder Executivo Estadual | AE38: =SUM(R38:AD38) -> 0
A39: =IF($B39="","",COUNTA($B$4:$B39)) -> 36 | B39: Solos | C39: A Solos é uma startup que desenvolve soluções integradas para estimular o descarte correto, fortalecer cooperativas e aprimorar a logística reversa. | D39: Logística reversa; Educação ambiental; Inclusão produtiva | E39: SOLOS (startup de economia circular) | F39: 29.569.087/0001-02 | G39: 30/01/2018 | H39: 7490-1/99 - Outras atividades profissionais, científicas e técnicas não especificadas anteriormente | I39: Salvador – BA (sede principal da SOLOS; atuação nacional) | J39: -12.9777 | K39: -38.5016 | L39: =IF($P39="","",IF(OR(LEFT($P39,2)="1.",LEFT($P39,2)="4."),"Lucas",IF(OR(LEFT($P39,2)="2.",LEFT($P39,2)="3."),"Caio","Leide"))) -> Leide | M39: Salvador | N39: BA | O39: Mata Atlântica | P39: 5. Economia Circular e Solidária | R39: Terciário | S39: Sociedade Empresária Limitada | AE39: =SUM(R39:AD39) -> 0
A40: =IF($B40="","",COUNTA($B$4:$B40)) -> 37 | B40: Programa Alagoas Catador | C40: O programa estimula a expansão da coleta seletiva, o reaproveitamento e a reciclagem de resíduos sólidos, e a valorização do trabalho dos catadores como agentes fundamentais da gestão de resíduos. | D40: Valorização dos catadores/as; capacitação; coleta seletiva; Inclusão produtiva | E40: Governo do Estado de Alagoas (Programa Alagoas Catador) | F40: 03.626.198/0001-01 | G40: 27/12/1999 | H40: 8411-6/00 - Administração pública em geral | I40: Av. General Luiz de França Albuquerque, s/n, Jacarecica, Maceió - AL | J40: -9.6498 | K40: -35.7089 | L40: =IF($P40="","",IF(OR(LEFT($P40,2)="1.",LEFT($P40,2)="4."),"Lucas",IF(OR(LEFT($P40,2)="2.",LEFT($P40,2)="3."),"Caio","Leide"))) -> Leide | M40: Maceió | N40: AL | O40: Mata Atlântica, Cerrado, Caatinga | P40: 5. Economia Circular e Solidária | R40: Terciário | S40: Órgão Público do Poder Executivo Estadual | AE40: =SUM(R40:AD40) -> 0
...

Sheet Dashboard
A1: id | B1: iniciativa | C1: objetivo | D1: tematica | E1: organizacao | F1: cnpj | G1: data_fundacao | H1: municipio | I1: estado | J1: bioma | K1: eixo | L1: setor | M1: natureza_juridica | N1: avaliador | O1: lat | P1: lon | Q1: pontuacao
A2: =IF('Exercício - Matriz de avaliação'!A4="","",'Exercício - Matriz de avaliação'!A4) -> 1 | B2: =IF('Exercício - Matriz de avaliação'!B4="","",'Exercício - Matriz de avaliação'!B4) -> Acreditar Microcrédito | C2: =IF('Exercício - Matriz de avaliação'!C4="","",'Exercício - Matriz de avaliação'!C4) -> Oferecer microcrédito produtivo orientado e educação financeira para grupo de mulheres e jovens, com foco em pequenos empreendimentos e agricultura familiar. O projeto tem apoio da Aliança Empreendedora. | D2: =IF('Exercício - Matriz de avaliação'!D4="","",'Exercício - Matriz de avaliação'!D4) -> Microcrédito; Finanças solidárias | E2: =IF('Exercício - Matriz de avaliação'!E4="","",'Exercício - Matriz de avaliação'!E4) -> Acreditar Sociedade de Crédito ao Microempreendedor (com apoio da Aliança Empreendedora) | F2: =IF('Exercício - Matriz de avaliação'!F4="","",'Exercício - Matriz de avaliação'!F4) -> 08.834.501/0001-85 | G2: =IF('Exercício - Matriz de avaliação'!G4="","",'Exercício - Matriz de avaliação'!G4) -> 27/04/2007 | H2: =IF('Exercício - Matriz de avaliação'!M4="","",'Exercício - Matriz de avaliação'!M4) -> Glória do Goitá | I2: =IF('Exercício - Matriz de avaliação'!N4="","",'Exercício - Matriz de avaliação'!N4) -> PE | J2: =IF('Exercício - Matriz de avaliação'!O4="","",'Exercício - Matriz de avaliação'!O4) -> Mata Atlântica | K2: =IF('Exercício - Matriz de avaliação'!P4="","",'Exercício - Matriz de avaliação'!P4) -> 1. Finanças Sustentáveis e Inclusivas | L2: =IF('Exercício - Matriz de avaliação'!R4="","",'Exercício - Matriz de avaliação'!R4) -> Terciário | M2: =IF('Exercício - Matriz de avaliação'!S4="","",'Exercício - Matriz de avaliação'!S4) -> Associação Privada | N2: =IF('Exercício - Matriz de avaliação'!L4="","",'Exercício - Matriz de avaliação'!L4) -> Lucas | O2: =IF('Exercício - Matriz de avaliação'!J4="","",'Exercício - Matriz de avaliação'!J4) -> -8.0017 | P2: =IF('Exercício - Matriz de avaliação'!K4="","",'Exercício - Matriz de avaliação'!K4) -> -35.2928 | Q2: =IF('Exercício - Matriz de avaliação'!AE4="","",'Exercício - Matriz de avaliação'!AE4) -> 0
A3: =IF('Exercício - Matriz de avaliação'!A5="","",'Exercício - Matriz de avaliação'!A5) -> 2 | B3: =IF('Exercício - Matriz de avaliação'!B5="","",'Exercício - Matriz de avaliação'!B5) -> Banco Palmas | C3: =IF('Exercício - Matriz de avaliação'!C5="","",'Exercício - Matriz de avaliação'!C5) -> Democratizar o acesso a serviços financeiros e bancários para a população de baixa renda do Conjunto Palmeiras, impulsionando o desenvolvimento socioeconômico local por meio de banco comunitário, microcrédito, moeda social e apoio a empreendedores do bairro | D3: =IF('Exercício - Matriz de avaliação'!D5="","",'Exercício - Matriz de avaliação'!D5) -> Banco comunitário; moeda social | E3: =IF('Exercício - Matriz de avaliação'!E5="","",'Exercício - Matriz de avaliação'!E5) -> Instituto Palmas de Desenvolvimento e Socioeconomia Solidária | F3: =IF('Exercício - Matriz de avaliação'!F5="","",'Exercício - Matriz de avaliação'!F5) -> 05.705.438/0001-99 | G3: =IF('Exercício - Matriz de avaliação'!G5="","",'Exercício - Matriz de avaliação'!G5) -> 17/06/2003 | H3: =IF('Exercício - Matriz de avaliação'!M5="","",'Exercício - Matriz de avaliação'!M5) -> Fortaleza | I3: =IF('Exercício - Matriz de avaliação'!N5="","",'Exercício - Matriz de avaliação'!N5) -> CE | J3: =IF('Exercício - Matriz de avaliação'!O5="","",'Exercício - Matriz de avaliação'!O5) -> Mata Atlântica | K3: =IF('Exercício - Matriz de avaliação'!P5="","",'Exercício - Matriz de avaliação'!P5) -> 1. Finanças Sustentáveis e Inclusivas | L3: =IF('Exercício - Matriz de avaliação'!R5="","",'Exercício - Matriz de avaliação'!R5) -> Terciário | M3: =IF('Exercício - Matriz de avaliação'!S5="","",'Exercício - Matriz de avaliação'!S5) -> Associação Privada | N3: =IF('Exercício - Matriz de avaliação'!L5="","",'Exercício - Matriz de avaliação'!L5) -> Lucas | O3: =IF('Exercício - Matriz de avaliação'!J5="","",'Exercício - Matriz de avaliação'!J5) -> -3.7319 | P3: =IF('Exercício - Matriz de avaliação'!K5="","",'Exercício - Matriz de avaliação'!K5) -> -38.5267 | Q3: =IF('Exercício - Matriz de avaliação'!AE5="","",'Exercício - Matriz de avaliação'!AE5) -> 0
A4: =IF('Exercício - Matriz de avaliação'!A6="","",'Exercício - Matriz de avaliação'!A6) -> 3 | B4: =IF('Exercício - Matriz de avaliação'!B6="","",'Exercício - Matriz de avaliação'!B6) -> COGEFUR – Conselho Gestor do Fundo Rotativo | C4: =IF('Exercício - Matriz de avaliação'!C6="","",'Exercício - Matriz de avaliação'!C6) -> Articular e gerir fundos rotativos solidários em rede, fortalecendo cooperativas de crédito, associações comunitárias e iniciativas de agricultura familiar por meio de linhas de capital de giro e instrumentos de finanças solidárias. | D4: =IF('Exercício - Matriz de avaliação'!D6="","",'Exercício - Matriz de avaliação'!D6) -> Economia solidária; microcrédito | E4: =IF('Exercício - Matriz de avaliação'!E6="","",'Exercício - Matriz de avaliação'!E6) -> Conselho Gestor do Fundo Rotativo (COGEFUR) | F4: =IF('Exercício - Matriz de avaliação'!F6="","",'Exercício - Matriz de avaliação'!F6) -> 04.578.438/0001-02 | G4: =IF('Exercício - Matriz de avaliação'!G6="","",'Exercício - Matriz de avaliação'!G6) -> 04/07/2001 | H4: =IF('Exercício - Matriz de avaliação'!M6="","",'Exercício - Matriz de avaliação'!M6) -> Serrinha | I4: =IF('Exercício - Matriz de avaliação'!N6="","",'Exercício - Matriz de avaliação'!N6) -> BA | J4: =IF('Exercício - Matriz de avaliação'!O6="","",'Exercício - Matriz de avaliação'!O6) -> Caatinga | K4: =IF('Exercício - Matriz de avaliação'!P6="","",'Exercício - Matriz de avaliação'!P6) -> 1. Finanças Sustentáveis e Inclusivas | L4: =IF('Exercício - Matriz de avaliação'!R6="","",'Exercício - Matriz de avaliação'!R6) -> Terciário | M4: =IF('Exercício - Matriz de avaliação'!S6="","",'Exercício - Matriz de avaliação'!S6) -> Associação Privada | N4: =IF('Exercício - Matriz de avaliação'!L6="","",'Exercício - Matriz de avaliação'!L6) -> Lucas | O4: =IF('Exercício - Matriz de avaliação'!J6="","",'Exercício - Matriz de avaliação'!J6) -> -11.6644 | P4: =IF('Exercício - Matriz de avaliação'!K6="","",'Exercício - Matriz de avaliação'!K6) -> -39.0078 | Q4: =IF('Exercício - Matriz de avaliação'!AE6="","",'Exercício - Matriz de avaliação'!AE6) -> 0
A5: =IF('Exercício - Matriz de avaliação'!A7="","",'Exercício - Matriz de avaliação'!A7) -> 4 | B5: =IF('Exercício - Matriz de avaliação'!B7="","",'Exercício - Matriz de avaliação'!B7) -> Banco Comunitário de Araçoiaba | C5: =IF('Exercício - Matriz de avaliação'!C7="","",'Exercício - Matriz de avaliação'!C7) -> Promover inclusão financeira na RM de Recife por meio da moeda social Caiana, estimulando consumo em comércios locais e acesso a crédito popular. | D5: =IF('Exercício - Matriz de avaliação'!D7="","",'Exercício - Matriz de avaliação'!D7) -> Economia solidária; microcrédito | E5: =IF('Exercício - Matriz de avaliação'!E7="","",'Exercício - Matriz de avaliação'!E7) -> Associação Banco da Cidade (em parceria com a Realiz) | F5: =IF('Exercício - Matriz de avaliação'!F7="","",'Exercício - Matriz de avaliação'!F7) -> Não localizado | G5: =IF('Exercício - Matriz de avaliação'!G7="","",'Exercício - Matriz de avaliação'!G7) -> Não Localizado | H5: =IF('Exercício - Matriz de avaliação'!M7="","",'Exercício - Matriz de avaliação'!M7) -> Araçoiaba | I5: =IF('Exercício - Matriz de avaliação'!N7="","",'Exercício - Matriz de avaliação'!N7) -> PE | J5: =IF('Exercício - Matriz de avaliação'!O7="","",'Exercício - Matriz de avaliação'!O7) -> Mata Atlântica | K5: =IF('Exercício - Matriz de avaliação'!P7="","",'Exercício - Matriz de avaliação'!P7) -> 1. Finanças Sustentáveis e Inclusivas | L5: =IF('Exercício - Matriz de avaliação'!R7="","",'Exercício - Matriz de avaliação'!R7) -> Terciário | M5: =IF('Exercício - Matriz de avaliação'!S7="","",'Exercício - Matriz de avaliação'!S7) -> Não Localizado | N5: =IF('Exercício - Matriz de avaliação'!L7="","",'Exercício - Matriz de avaliação'!L7) -> Lucas | O5: =IF('Exercício - Matriz de avaliação'!J7="","",'Exercício - Matriz de avaliação'!J7) -> -7.7869 | P5: =IF('Exercício - Matriz de avaliação'!K7="","",'Exercício - Matriz de avaliação'!K7) -> -35.0922 | Q5: =IF('Exercício - Matriz de avaliação'!AE7="","",'Exercício - Matriz de avaliação'!AE7) -> 0
A6: =IF('Exercício - Matriz de avaliação'!A8="","",'Exercício - Matriz de avaliação'!A8) -> 5 | B6: =IF('Exercício - Matriz de avaliação'!B8="","",'Exercício - Matriz de avaliação'!B8) -> Rede de Ativadores de Crédito Socioambiental (Conexsus) | C6: =IF('Exercício - Matriz de avaliação'!C8="","",'Exercício - Matriz de avaliação'!C8) -> Implantar uma rede de ativadores e ativadoras de crédito socioambiental, formada por técnicos/as locais vinculados a negócios comunitários, para destravar o acesso ao crédito rural (especialmente Pronaf) por agricultores familiares, povos e comunidades tradicionais e organizações da sociobiodiversidade, combinando assistência técnica, educação financeira e financiamento crescente para aumento de renda e qualificação produtiva. | D6: =IF('Exercício - Matriz de avaliação'!D8="","",'Exercício - Matriz de avaliação'!D8) -> Microcrédito; Finanças solidárias | E6: =IF('Exercício - Matriz de avaliação'!E8="","",'Exercício - Matriz de avaliação'!E8) -> Instituto Conexões Sustentáveis (Conexsus) | F6: =IF('Exercício - Matriz de avaliação'!F8="","",'Exercício - Matriz de avaliação'!F8) -> 10.980.503/0001-24 | G6: =IF('Exercício - Matriz de avaliação'!G8="","",'Exercício - Matriz de avaliação'!G8) -> 27/05/2009 | H6: =IF('Exercício - Matriz de avaliação'!M8="","",'Exercício - Matriz de avaliação'!M8) | I6: =IF('Exercício - Matriz de avaliação'!N8="","",'Exercício - Matriz de avaliação'!N8) -> BA | J6: =IF('Exercício - Matriz de avaliação'!O8="","",'Exercício - Matriz de avaliação'!O8) -> Mata Atlântica, Caatinga, Cerrado | K6: =IF('Exercício - Matriz de avaliação'!P8="","",'Exercício - Matriz de avaliação'!P8) -> 1. Finanças Sustentáveis e Inclusivas | L6: =IF('Exercício - Matriz de avaliação'!R8="","",'Exercício - Matriz de avaliação'!R8) -> Terciário | M6: =IF('Exercício - Matriz de avaliação'!S8="","",'Exercício - Matriz de avaliação'!S8) -> Associação Privada | N6: =IF('Exercício - Matriz de avaliação'!L8="","",'Exercício - Matriz de avaliação'!L8) -> Lucas | O6: =IF('Exercício - Matriz de avaliação'!J8="","",'Exercício - Matriz de avaliação'!J8) -> -22.9068 | P6: =IF('Exercício - Matriz de avaliação'!K8="","",'Exercício - Matriz de avaliação'!K8) -> -43.1729 | Q6: =IF('Exercício - Matriz de avaliação'!AE8="","",'Exercício - Matriz de avaliação'!AE8) -> 0
A7: =IF('Exercício - Matriz de avaliação'!A9="","",'Exercício - Matriz de avaliação'!A9) -> 6 | B7: =IF('Exercício - Matriz de avaliação'!B9="","",'Exercício - Matriz de avaliação'!B9) -> Rede Xique Xique de Comercialização Solidária | C7: =IF('Exercício - Matriz de avaliação'!C9="","",'Exercício - Matriz de avaliação'!C9) -> Organizar grupos de agricultores/as familiares e empreendimentos de economia solidária para produzir, comercializar e certificar alimentos agroecológicos com base em certificação orgânica participativa, articulando agroecologia, feminismo e juventude. | D7: =IF('Exercício - Matriz de avaliação'!D9="","",'Exercício - Matriz de avaliação'!D9) -> Certificação; Serviços ecossistêmicos | E7: =IF('Exercício - Matriz de avaliação'!E9="","",'Exercício - Matriz de avaliação'!E9) -> Associação de Comercialização Solidária Xique-Xique | F7: =IF('Exercício - Matriz de avaliação'!F9="","",'Exercício - Matriz de avaliação'!F9) -> 07.194.162/0001-57 | G7: =IF('Exercício - Matriz de avaliação'!G9="","",'Exercício - Matriz de avaliação'!G9) -> 31/01/2005 | H7: =IF('Exercício - Matriz de avaliação'!M9="","",'Exercício - Matriz de avaliação'!M9) -> Mossoró | I7: =IF('Exercício - Matriz de avaliação'!N9="","",'Exercício - Matriz de avaliação'!N9) -> RN | J7: =IF('Exercício - Matriz de avaliação'!O9="","",'Exercício - Matriz de avaliação'!O9) -> Caatinga | K7: =IF('Exercício - Matriz de avaliação'!P9="","",'Exercício - Matriz de avaliação'!P9) -> 1. Finanças Sustentáveis e Inclusivas | L7: =IF('Exercício - Matriz de avaliação'!R9="","",'Exercício - Matriz de avaliação'!R9) -> Terciário | M7: =IF('Exercício - Matriz de avaliação'!S9="","",'Exercício - Matriz de avaliação'!S9) -> Associação Privada | N7: =IF('Exercício - Matriz de avaliação'!L9="","",'Exercício - Matriz de avaliação'!L9) -> Lucas | O7: =IF('Exercício - Matriz de avaliação'!J9="","",'Exercício - Matriz de avaliação'!J9) -> -5.1875 | P7: =IF('Exercício - Matriz de avaliação'!K9="","",'Exercício - Matriz de avaliação'!K9) -> -37.3441 | Q7: =IF('Exercício - Matriz de avaliação'!AE9="","",'Exercício - Matriz de avaliação'!AE9) -> 0
A8: =IF('Exercício - Matriz de avaliação'!A10="","",'Exercício - Matriz de avaliação'!A10) -> 7 | B8: =IF('Exercício - Matriz de avaliação'!B10="","",'Exercício - Matriz de avaliação'!B10) -> ID Hub Brazil (ID Incubator) | C8: =IF('Exercício - Matriz de avaliação'!C10="","",'Exercício - Matriz de avaliação'!C10) -> Iniciativa entre o governo brasileiro e o governo britânico para formação de um Centro de Descarbonização da Indústria do Brasil, é uma experiência piloto com abrangência nacional e com foco na NIB. Funciona como um escritório de apoio e suporte aos projetos industriais que buscam se adaptar ao processo de transformação ecológica da economia brasileira | D8: =IF('Exercício - Matriz de avaliação'!D10="","",'Exercício - Matriz de avaliação'!D10) -> Facillity; Hub | E8: =IF('Exercício - Matriz de avaliação'!E10="","",'Exercício - Matriz de avaliação'!E10) -> MDIC – Ministério do Desenvolvimento, Indústria, Comércio e Serviços (parceria UNIDO/DESNZ-Reino Unido) | F8: =IF('Exercício - Matriz de avaliação'!F10="","",'Exercício - Matriz de avaliação'!F10) -> 00.394.478/0001-43 | G8: =IF('Exercício - Matriz de avaliação'!G10="","",'Exercício - Matriz de avaliação'!G10) -> 29/11/1974 | H8: =IF('Exercício - Matriz de avaliação'!M10="","",'Exercício - Matriz de avaliação'!M10) -> Brasília | I8: =IF('Exercício - Matriz de avaliação'!N10="","",'Exercício - Matriz de avaliação'!N10) -> BA, PE, CE, RN, AL, PI, PB, SE, MA | J8: =IF('Exercício - Matriz de avaliação'!O10="","",'Exercício - Matriz de avaliação'!O10) -> Cerrado, Caatinga, Mata Atlântica, Amazônia | K8: =IF('Exercício - Matriz de avaliação'!P10="","",'Exercício - Matriz de avaliação'!P10) -> 1. Finanças Sustentáveis e Inclusivas | L8: =IF('Exercício - Matriz de avaliação'!R10="","",'Exercício - Matriz de avaliação'!R10) -> Terciário | M8: =IF('Exercício - Matriz de avaliação'!S10="","",'Exercício - Matriz de avaliação'!S10) -> Órgão Público do Poder Executivo Federal | N8: =IF('Exercício - Matriz de avaliação'!L10="","",'Exercício - Matriz de avaliação'!L10) -> Lucas | O8: =IF('Exercício - Matriz de avaliação'!J10="","",'Exercício - Matriz de avaliação'!J10) -> -15.7942 | P8: =IF('Exercício - Matriz de avaliação'!K10="","",'Exercício - Matriz de avaliação'!K10) -> -47.8822 | Q8: =IF('Exercício - Matriz de avaliação'!AE10="","",'Exercício - Matriz de avaliação'!AE10) -> 0
A9: =IF('Exercício - Matriz de avaliação'!A11="","",'Exercício - Matriz de avaliação'!A11) -> 8 | B9: =IF('Exercício - Matriz de avaliação'!B11="","",'Exercício - Matriz de avaliação'!B11) -> Projeto Pacto Global de Jovens pelo Clima - ONU | C9: =IF('Exercício - Matriz de avaliação'!C11="","",'Exercício - Matriz de avaliação'!C11) -> Preparar jovens estudantes, por meio da educação ambiental ativa e participativa, para ocupar os espaços de poder ativamente na luta por justiça socioambiental no contexto das crises climáticas para que se tornem " sentinelas" em defesa do desenvolvimento sustentável local. | D9: =IF('Exercício - Matriz de avaliação'!D11="","",'Exercício - Matriz de avaliação'!D11) -> Educação ambiental, soluções inovadoras de impacto social. | E9: =IF('Exercício - Matriz de avaliação'!E11="","",'Exercício - Matriz de avaliação'!E11) -> Organização das Nações Unidas (ONU) – Pacto Global | F9: =IF('Exercício - Matriz de avaliação'!F11="","",'Exercício - Matriz de avaliação'!F11) -> 37.321.091/0001-77 | G9: =IF('Exercício - Matriz de avaliação'!G11="","",'Exercício - Matriz de avaliação'!G11) -> 11/05/2020 | H9: =IF('Exercício - Matriz de avaliação'!M11="","",'Exercício - Matriz de avaliação'!M11) -> Recife | I9: =IF('Exercício - Matriz de avaliação'!N11="","",'Exercício - Matriz de avaliação'!N11) -> PE | J9: =IF('Exercício - Matriz de avaliação'!O11="","",'Exercício - Matriz de avaliação'!O11) -> Mata Atlântica | K9: =IF('Exercício - Matriz de avaliação'!P11="","",'Exercício - Matriz de avaliação'!P11) -> 2. Adensamento Tecnológico | L9: =IF('Exercício - Matriz de avaliação'!R11="","",'Exercício - Matriz de avaliação'!R11) -> Terciário | M9: =IF('Exercício - Matriz de avaliação'!S11="","",'Exercício - Matriz de avaliação'!S11) -> Associação Privada | N9: =IF('Exercício - Matriz de avaliação'!L11="","",'Exercício - Matriz de avaliação'!L11) -> Caio | O9: =IF('Exercício - Matriz de avaliação'!J11="","",'Exercício - Matriz de avaliação'!J11) -> -8.0476 | P9: =IF('Exercício - Matriz de avaliação'!K11="","",'Exercício - Matriz de avaliação'!K11) -> -34.877 | Q9: =IF('Exercício - Matriz de avaliação'!AE11="","",'Exercício - Matriz de avaliação'!AE11) -> 0
